<?xml version="1.0"?>
<robot xmlns:xacro="http://www.ros.org/wiki/xacro" name="robot">

    <link name="base_link">
        <visual>
            <geometry><box size="0.4 0.3 0.15"/></geometry>
        </visual>
        <collision>
            <geometry><box size="0.4 0.3 0.15"/></geometry>
        </collision>
        <inertial>
            <origin xyz="0 0 0" rpy="0 0 0"/>
            <mass value="1.0"/>
            <inertia ixx="0.01" ixy="0.0" ixz="0.0" iyy="0.01" iyz="0.0" izz="0.01"/>
        </inertial>
    </link>

    <link name="laser_frame">
        <visual>
            <geometry><cylinder radius="0.05" length="0.04"/></geometry>
        </visual>
        <collision>
            <geometry><cylinder radius="0.05" length="0.04"/></geometry>
        </collision>
        <inertial>
            <origin xyz="0 0 0" rpy="0 0 0"/>
            <mass value="0.1"/>
            <inertia ixx="0.001" ixy="0.0" ixz="0.0" iyy="0.001" iyz="0.0" izz="0.001"/>
        </inertial>
    </link>

    <!-- LEFT WHEEL -->
    <link name="left_wheel">
        <visual>
            <geometry><cylinder radius="0.05" length="0.04"/></geometry>
        </visual>
        <collision>
            <geometry><cylinder radius="0.05" length="0.04"/></geometry>
        </collision>
        <inertial>
            <origin xyz="0 0 0" rpy="0 0 0"/>
            <mass value="0.1"/>
            <inertia ixx="0.001" ixy="0.0" ixz="0.0" iyy="0.001" iyz="0.0" izz="0.001"/>
        </inertial>
    </link>
    <joint name="left_wheel_joint" type="continuous">
        <parent link="base_link"/><child link="left_wheel"/><origin xyz="0 0.175 0" rpy="-1.57 0 0"/><axis xyz="0 0 1"/>
    </joint>

    <joint name="laser_joint" type="fixed">
        <parent link="base_link"/><child link="laser_frame"/><origin xyz="0.1 0 0.1" rpy="0 0 0"/>
    </joint>

    <!-- RIGHT WHEEL -->
    <link name="right_wheel">
        <visual>
            <geometry><cylinder radius="0.05" length="0.04"/></geometry>
        </visual>
        <collision>
            <geometry><cylinder radius="0.05" length="0.04"/></geometry>
        </collision>
        <inertial>
            <origin xyz="0 0 0" rpy="0 0 0"/>
            <mass value="0.1"/>
            <inertia ixx="0.001" ixy="0.0" ixz="0.0" iyy="0.001" iyz="0.0" izz="0.001"/>
        </inertial>
    </link>
    <joint name="right_wheel_joint" type="continuous">
        <parent link="base_link"/><child link="right_wheel"/><origin xyz="0 -0.175 0" rpy="1.57 0 0"/><axis xyz="0 0 1"/>
    </joint>

    </robot>